<?xml version="1.0" encoding="utf-8"?>
<!-- This URDF was automatically created by SolidWorks to URDF Exporter! Originally created by Stephen Brawner (brawner@gmail.com) 
     Commit Version: 1.6.0-4-g7f85cfe  Build Version: 1.6.7995.38578
     For more information, please see http://wiki.ros.org/sw_urdf_exporter -->
<robot
  name="robot_car_rev08">
  <link
    name="dummy_link">
  </link>
  <link
    name="chassis">
    <inertial>
      <origin
        xyz="-0.064890969251821 4.3352058692555E-05 0.102992440037782"
        rpy="0 0 0" />
      <mass
        value="42.551942744192" />
      <inertia
        ixx="0.607232687971123"
        ixy="2.60230726055755E-11"
        ixz="-0.0249348609919036"
        iyy="2.62951463079903"
        iyz="3.65729745160199E-12"
        izz="3.125839901728" />
    </inertial>
    <visual>
      <origin
        xyz="0 0 0"
        rpy="0 0 0" />
      <geometry>
        <mesh
          filename="package://robot_car_rev08/meshes/chassis.STL" />
      </geometry>
      <material
        name="">
        <color
          rgba="1 1 1 0.35" />
      </material>
    </visual>
    <collision>
      <origin
        xyz="0 0 0"
        rpy="0 0 0" />
      <geometry>
        <mesh
          filename="package://robot_car_rev08/meshes/chassis.STL" />
      </geometry>
    </collision>
  </link>
  <link
    name="front_left_steering">
    <inertial>
      <origin
        xyz="-0.00843161115072408 -0.00203498762992196 0.00125939614783174"
        rpy="0 0 0" />
      <mass
        value="0.0463597443861658" />
      <inertia
        ixx="5.56376884726499E-06"
        ixy="9.62339372922729E-07"
        ixz="-4.48945411160145E-07"
        iyy="7.38231131477921E-06"
        iyz="9.02997774269345E-07"
        izz="8.3434006246681E-06" />
    </inertial>
    <visual>
      <origin
        xyz="0 0 0"
        rpy="0 0 0" />
      <geometry>
        <mesh
          filename="package://robot_car_rev08/meshes/front_left_steering.STL" />
      </geometry>
      <material
        name="">
        <color
          rgba="0.898039215686275 0.917647058823529 0.929411764705882 1" />
      </material>
    </visual>
    <collision>
      <origin
        xyz="0 0 0"
        rpy="0 0 0" />
      <geometry>
        <mesh
          filename="package://robot_car_rev08/meshes/front_left_steering.STL" />
      </geometry>
    </collision>
  </link>
  <!--Joint Definitions-->
  <!--Joint dummy_link - chassis-->
  <joint
    name="dummy_joint"
    type="fixed">
    <origin
      xyz="0 0 0"
      rpy="0 0 0"/>
    <parent
      link="dummy_link"/>
    <child
      link="chassis"/>
    </joint>
  <joint
    name="front_left_steering_joint"
    type="revolute">
    <origin
      xyz="0.254 0.203182499373019 0.101600000000001"
      rpy="0.13962634015954 0 -1.5707963267949" />
    <parent
      link="chassis" />
    <child
      link="front_left_steering" />
    <axis
      xyz="0 0 1" />
    <limit
      lower="-1.0472"
      upper="1.0472"
      effort="2"
      velocity="0.5" />
  </joint>
  <link
    name="front_left_wheel">
    <inertial>
      <origin
        xyz="0.000710628409286707 -9.98723098043965E-05 1.01391735665979E-05"
        rpy="0 0 0" />
      <mass
        value="1.92553427383926" />
      <inertia
        ixx="0.00638023684004655"
        ixy="-1.20952159865865E-18"
        ixz="-8.11582122336904E-19"
        iyy="0.00638023684004655"
        iyz="3.39909203718336E-19"
        izz="0.0111123897410484" />
    </inertial>
    <visual>
      <origin
        xyz="0 0 0"
        rpy="0 0 0" />
      <geometry>
        <mesh
          filename="package://robot_car_rev08/meshes/front_left_wheel.STL" />
      </geometry>
      <material
        name="">
        <color
          rgba="0.298039215686275 0.298039215686275 0.298039215686275 1" />
      </material>
    </visual>
    <collision>
      <origin
        xyz="0 0 0"
        rpy="0 0 0" />
      <geometry>
        <mesh
          filename="package://robot_car_rev08/meshes/front_left_wheel.STL" />
      </geometry>
    </collision>
  </link>
  <joint
    name="front_left_wheel_joint"
    type="continuous">
    <origin
      xyz="-0.0253999999999999 0 0"
      rpy="1.5707963267949 -0.13962634015954 -1.5707963267949" />
    <parent
      link="front_left_steering" />
    <child
      link="front_left_wheel" />
    <axis
      xyz="0 0 1" />
  </joint>
  <link
    name="front_right_steering">
    <inertial>
      <origin
        xyz="0.00843160845688481 -0.00203498278844419 0.00125938690317389"
        rpy="0 0 0" />
      <mass
        value="0.0171702882340771" />
      <inertia
        ixx="2.06065663437465E-06"
        ixy="-3.56421686036717E-07"
        ixz="1.66275327091769E-07"
        iyy="2.73419165997558E-06"
        iyz="3.34444901736521E-07"
        izz="3.09014802274599E-06" />
    </inertial>
    <visual>
      <origin
        xyz="0 0 0"
        rpy="0 0 0" />
      <geometry>
        <mesh
          filename="package://robot_car_rev08/meshes/front_right_steering.STL" />
      </geometry>
      <material
        name="">
        <color
          rgba="0.792156862745098 0.819607843137255 0.933333333333333 1" />
      </material>
    </visual>
    <collision>
      <origin
        xyz="0 0 0"
        rpy="0 0 0" />
      <geometry>
        <mesh
          filename="package://robot_car_rev08/meshes/front_right_steering.STL" />
      </geometry>
    </collision>
  </link>
  <joint
    name="front_right_steering_joint"
    type="revolute">
    <origin
      xyz="0.254 -0.203182499373019 0.101600000000001"
      rpy="0.13962634015954 0 -1.5707963267949" />
    <parent
      link="chassis" />
    <child
      link="front_right_steering" />
    <axis
      xyz="0 0 1" />
    <limit
      lower="-1.0472"
      upper="1.0472"
      effort="2"
      velocity="0.5" />
  </joint>
  <link
    name="front_right_wheel">
    <inertial>
      <origin
        xyz="0 4.00229910539665E-16 0"
        rpy="0 0 0" />
      <mass
        value="1.92553427383926" />
      <inertia
        ixx="0.00638023684004654"
        ixy="2.68698531563788E-19"
        ixz="-8.44436911313644E-19"
        iyy="0.00638023684004654"
        iyz="4.28846497279084E-20"
        izz="0.0111123897410484" />
    </inertial>
    <visual>
      <origin
        xyz="0 0 0"
        rpy="0 0 0" />
      <geometry>
        <mesh
          filename="package://robot_car_rev08/meshes/front_right_wheel.STL" />
      </geometry>
      <material
        name="">
        <color
          rgba="0.298039215686275 0.298039215686275 0.298039215686275 1" />
      </material>
    </visual>
    <collision>
      <origin
        xyz="0 0 0"
        rpy="0 0 0" />
      <geometry>
        <mesh
          filename="package://robot_car_rev08/meshes/front_right_wheel.STL" />
      </geometry>
    </collision>
  </link>
  <joint
    name="front_right_wheel_joint"
    type="continuous">
    <origin
      xyz="0.0253999999999999 0 0"
      rpy="1.5707963267949 -0.13962634015954 -1.5707963267949" />
    <parent
      link="front_right_steering" />
    <child
      link="front_right_wheel" />
    <axis
      xyz="0 0 -1" />
  </joint>
  <link
    name="rear_wheel">
    <inertial>
      <origin
        xyz="-5.55111512312578E-17 -3.66518240186853E-16 -0.1905"
        rpy="0 0 0" />
      <mass
        value="4.14898028838973" />
      <inertia
        ixx="0.0170343666536348"
        ixy="-5.09490689039691E-20"
        ixz="3.62104180661535E-19"
        iyy="0.0170343666536348"
        iyz="-9.84772981696711E-19"
        izz="0.0222389259821933" />
    </inertial>
    <visual>
      <origin
        xyz="0 0 0"
        rpy="0 0 0" />
      <geometry>
        <mesh
          filename="package://robot_car_rev08/meshes/rear_wheel.STL" />
      </geometry>
      <material
        name="">
        <color
          rgba="0.898039215686275 0.917647058823529 0.929411764705882 1" />
      </material>
    </visual>
    <collision>
      <origin
        xyz="0 0 0"
        rpy="0 0 0" />
      <geometry>
        <mesh
          filename="package://robot_car_rev08/meshes/rear_wheel.STL" />
      </geometry>
    </collision>
  </link>
  <joint
    name="rear_wheel_joint"
    type="continuous">
    <origin
      xyz="-0.253999999999999 0.1905 0.101600000000001"
      rpy="1.5707963267949 0 3.14159265358979" />
    <parent
      link="chassis" />
    <child
      link="rear_wheel" />
    <axis
      xyz="0 0 1" />
  </joint>
    <!--Transmisison Definitions-->
  <transmission name="rear_transmission">
    <type>transmission_interface/SimpleTransmission</type>
    <joint name="rear_wheel_joint">
      <hardwareInterface>hardware_interface/VelocityJointInterface</hardwareInterface>
    </joint>
    <actuator name="rear_motor">
      <mechanicalReduction>1</mechanicalReduction>
    </actuator>
  </transmission>
  <transmission name="front_left_steering_transmission">
    <type>transmission_interface/SimpleTransmission</type>
    <joint name="front_left_steering_joint">
      <hardwareInterface>hardware_interface/EffortJointInterface</hardwareInterface>
    </joint>
    <actuator name="front_left_motor">
      <mechanicalReduction>1</mechanicalReduction>
    </actuator>
  </transmission>
  <transmission name="front_right_steering_transmission">
    <type>transmission_interface/SimpleTransmission</type>
    <joint name="front_right_steering_joint">
      <hardwareInterface>hardware_interface/EffortJointInterface</hardwareInterface>
    </joint>
    <actuator name="front_right_motor">
      <mechanicalReduction>1</mechanicalReduction>
    </actuator>
  </transmission>
</robot>