<?xml version="1.0" ?>
<!-- =================================================================================== -->
<!-- |    This document was autogenerated by xacro from robot_car_rev08.xacro          | -->
<!-- |    EDITING THIS FILE BY HAND IS NOT RECOMMENDED                                 | -->
<!-- =================================================================================== -->
<!-- Name your robot here -->
<robot name="robot_car_rev08">
  <link name="dummy_link">
  </link>
  <link name="chassis">
    <inertial>
      <origin rpy="0 0 0" xyz="-0.064890969251821 4.3352058692555E-05 0.102992440037782"/>
      <mass value="42.551942744192"/>
      <inertia ixx="0.607232687971123" ixy="2.60230726055755E-11" ixz="-0.0249348609919036" iyy="2.62951463079903" iyz="3.65729745160199E-12" izz="3.125839901728"/>
    </inertial>
    <visual>
      <origin rpy="0 0 0" xyz="0 0 0"/>
      <geometry>
        <mesh filename="package://robot_car_rev08/meshes/chassis.STL"/>
      </geometry>
      <material name="">
        <color rgba="1 1 1 0.35"/>
      </material>
    </visual>
    <collision>
      <origin rpy="0 0 0" xyz="0 0 0"/>
      <geometry>
        <mesh filename="package://robot_car_rev08/meshes/chassis.STL"/>
      </geometry>
    </collision>
  </link>
  <link name="front_left_steering">
    <inertial>
      <origin rpy="0 0 0" xyz="-0.00843161115072408 -0.00203498762992196 0.00125939614783174"/>
      <mass value="0.0463597443861658"/>
      <inertia ixx="5.56376884726499E-06" ixy="9.62339372922729E-07" ixz="-4.48945411160145E-07" iyy="7.38231131477921E-06" iyz="9.02997774269345E-07" izz="8.3434006246681E-06"/>
    </inertial>
    <visual>
      <origin rpy="0 0 0" xyz="0 0 0"/>
      <geometry>
        <mesh filename="package://robot_car_rev08/meshes/front_left_steering.STL"/>
      </geometry>
      <material name="">
        <color rgba="0.898039215686275 0.917647058823529 0.929411764705882 1"/>
      </material>
    </visual>
    <collision>
      <origin rpy="0 0 0" xyz="0 0 0"/>
      <geometry>
        <mesh filename="package://robot_car_rev08/meshes/front_left_steering.STL"/>
      </geometry>
    </collision>
  </link>
  <!--Joint Definitions-->
  <!--Joint dummy_link - chassis-->
  <joint name="dummy_joint" type="fixed">
    <origin rpy="0 0 0" xyz="0 0 0"/>
    <parent link="dummy_link"/>
    <child link="chassis"/>
  </joint>
  <joint name="front_left_steering_joint" type="revolute">
    <origin rpy="0.13962634015954 0 -1.5707963267949" xyz="0.254 0.203182499373019 0.101600000000001"/>
    <parent link="chassis"/>
    <child link="front_left_steering"/>
    <axis xyz="0 0 1"/>
    <limit effort="25" lower="-1.0472" upper="1.0472" velocity="100"/>
  </joint>
  <link name="front_left_wheel">
    <inertial>
      <origin rpy="0 0 0" xyz="0.000710628409286707 -9.98723098043965E-05 1.01391735665979E-05"/>
      <mass value="1.92553427383926"/>
      <inertia ixx="0.00638023684004655" ixy="-1.20952159865865E-18" ixz="-8.11582122336904E-19" iyy="0.00638023684004655" iyz="3.39909203718336E-19" izz="0.0111123897410484"/>
    </inertial>
    <visual>
      <origin rpy="0 0 0" xyz="0 0 0"/>
      <geometry>
        <mesh filename="package://robot_car_rev08/meshes/front_left_wheel.STL"/>
      </geometry>
      <material name="">
        <color rgba="0.298039215686275 0.298039215686275 0.298039215686275 1"/>
      </material>
    </visual>
    <collision>
      <origin rpy="0 0 0" xyz="0 0 0"/>
      <geometry>
        <mesh filename="package://robot_car_rev08/meshes/front_left_wheel.STL"/>
      </geometry>
    </collision>
  </link>
  <joint name="front_left_wheel_joint" type="continuous">
    <origin rpy="1.5707963267949 -0.13962634015954 -1.5707963267949" xyz="-0.0253999999999999 0 0"/>
    <parent link="front_left_steering"/>
    <child link="front_left_wheel"/>
    <axis xyz="0 0 1"/>
  </joint>
  <link name="front_right_steering">
    <inertial>
      <origin rpy="0 0 0" xyz="0.00843160845688481 -0.00203498278844419 0.00125938690317389"/>
      <mass value="0.0171702882340771"/>
      <inertia ixx="2.06065663437465E-06" ixy="-3.56421686036717E-07" ixz="1.66275327091769E-07" iyy="2.73419165997558E-06" iyz="3.34444901736521E-07" izz="3.09014802274599E-06"/>
    </inertial>
    <visual>
      <origin rpy="0 0 0" xyz="0 0 0"/>
      <geometry>
        <mesh filename="package://robot_car_rev08/meshes/front_right_steering.STL"/>
      </geometry>
      <material name="">
        <color rgba="0.792156862745098 0.819607843137255 0.933333333333333 1"/>
      </material>
    </visual>
    <collision>
      <origin rpy="0 0 0" xyz="0 0 0"/>
      <geometry>
        <mesh filename="package://robot_car_rev08/meshes/front_right_steering.STL"/>
      </geometry>
    </collision>
  </link>
  <joint name="front_right_steering_joint" type="revolute">
    <origin rpy="0.13962634015954 0 -1.5707963267949" xyz="0.254 -0.203182499373019 0.101600000000001"/>
    <parent link="chassis"/>
    <child link="front_right_steering"/>
    <axis xyz="0 0 1"/>
    <limit effort="25" lower="-1.0472" upper="1.0472" velocity="100"/>
  </joint>
  <link name="front_right_wheel">
    <inertial>
      <origin rpy="0 0 0" xyz="0 4.00229910539665E-16 0"/>
      <mass value="1.92553427383926"/>
      <inertia ixx="0.00638023684004654" ixy="2.68698531563788E-19" ixz="-8.44436911313644E-19" iyy="0.00638023684004654" iyz="4.28846497279084E-20" izz="0.0111123897410484"/>
    </inertial>
    <visual>
      <origin rpy="0 0 0" xyz="0 0 0"/>
      <geometry>
        <mesh filename="package://robot_car_rev08/meshes/front_right_wheel.STL"/>
      </geometry>
      <material name="">
        <color rgba="0.298039215686275 0.298039215686275 0.298039215686275 1"/>
      </material>
    </visual>
    <collision>
      <origin rpy="0 0 0" xyz="0 0 0"/>
      <geometry>
        <mesh filename="package://robot_car_rev08/meshes/front_right_wheel.STL"/>
      </geometry>
    </collision>
  </link>
  <joint name="front_right_wheel_joint" type="continuous">
    <origin rpy="1.5707963267949 -0.13962634015954 -1.5707963267949" xyz="0.0253999999999999 0 0"/>
    <parent link="front_right_steering"/>
    <child link="front_right_wheel"/>
    <axis xyz="0 0 -1"/>
  </joint>
  <link name="rear_wheel">
    <inertial>
      <origin rpy="0 0 0" xyz="-5.55111512312578E-17 -3.66518240186853E-16 -0.1905"/>
      <mass value="4.14898028838973"/>
      <inertia ixx="0.0170343666536348" ixy="-5.09490689039691E-20" ixz="3.62104180661535E-19" iyy="0.0170343666536348" iyz="-9.84772981696711E-19" izz="0.0222389259821933"/>
    </inertial>
    <visual>
      <origin rpy="0 0 0" xyz="0 0 0"/>
      <geometry>
        <mesh filename="package://robot_car_rev08/meshes/rear_wheel.STL"/>
      </geometry>
      <material name="">
        <color rgba="0.898039215686275 0.917647058823529 0.929411764705882 1"/>
      </material>
    </visual>
    <collision>
      <origin rpy="0 0 0" xyz="0 0 0"/>
      <geometry>
        <mesh filename="package://robot_car_rev08/meshes/rear_wheel.STL"/>
      </geometry>
    </collision>
  </link>
  <joint name="rear_wheel_joint" type="continuous">
    <origin rpy="1.5707963267949 0 3.14159265358979" xyz="-0.253999999999999 0.1905 0.101600000000001"/>
    <parent link="chassis"/>
    <child link="rear_wheel"/>
    <axis xyz="0 0 1"/>
  </joint>
  <!--Transmisison Definitions-->
  <transmission name="rear_transmission">
    <type>transmission_interface/SimpleTransmission</type>
    <joint name="rear_wheel_joint">
      <hardwareInterface>hardware_interface/VelocityJointInterface</hardwareInterface>
    </joint>
    <actuator name="rear_motor">
      <mechanicalReduction>1</mechanicalReduction>
    </actuator>
  </transmission>
  <transmission name="front_left_steering_transmission">
    <type>transmission_interface/SimpleTransmission</type>
    <joint name="front_left_steering_joint">
      <hardwareInterface>hardware_interface/EffortJointInterface</hardwareInterface>
    </joint>
    <actuator name="front_left_motor">
      <mechanicalReduction>1</mechanicalReduction>
    </actuator>ev06
  </transmission>
  <transmission name="front_right_steering_transmission">
    <type>transmission_interface/SimpleTransmission</type>
    <joint name="front_right_steering_joint">
      <hardwareInterface>hardware_interface/EffortJointInterface</hardwareInterface>
    </joint>
    <actuator name="front_right_motor">
      <mechanicalReduction>1</mechanicalReduction>
    </actuator>
  </transmission>
  <link name="base_laser">
    <inertial>
      <origin rpy="0 0 0" xyz="-0.00029774 0.0066667 0.00013047"/>
      <mass value="0.15717"/>
      <inertia ixx="6.7885E-05" ixy="-1.3987E-07" ixz="-8.1554E-07" iyy="0.00013173" iyz="-9.0932E-08" izz="7.1972E-05"/>
    </inertial>
    <visual>
      <origin rpy="0 0 0" xyz="0 0 0"/>
      <geometry>
        <mesh filename="package://robot_car_rev08/meshes/ydlidar.dae"/>
      </geometry>
      <material name="">
        <color rgba="0.64706 0.61961 0.58824 1"/>
      </material>
    </visual>
    <collision>
      <origin rpy="0 0 0" xyz="0 0 0"/>
      <geometry>
        <mesh filename="package://robot_car_rev08/meshes/ydlidar.dae"/>
      </geometry>
    </collision>
  </link>
  <link name="laser_frame">
    <inertial>
      <origin rpy="0 0 0" xyz="-0.00036659 0.00064155 -0.00027052"/>
      <mass value="0.25482"/>
      <inertia ixx="8.9194E-05" ixy="1.8116E-07" ixz="3.6435E-08" iyy="0.00018279" iyz="2.423E-07" izz="0.00011103"/>
    </inertial>
    <!--visual>
      <origin
        xyz="0 0 0"
        rpy="0 0 0" />
      <geometry>
        <mesh
          filename="package://ydlidar_ros/meshes/ydlidar.dae" />
      </geometry>
      <material
        name="">
        <color
          rgba="0.64706 0.61961 0.58824 1" />
      </material>
    </visual-->
    <!--collision>
      <origin
        xyz="0 0 0"
        rpy="0 0 0" />
      <geometry>
        <mesh
          filename="package://ydlidar_ros/meshes/ydlidar.dae" />
      </geometry>
    </collision-->
  </link>
  <joint name="laser_joint" type="fixed">
    <origin rpy="0 0 0" xyz="0 0 0.03172"/>
    <parent link="base_laser"/>
    <child link="laser_frame"/>
    <axis xyz="0 0 0"/>
  </joint>
  <!-- Add your gazebo sensors here -->
  <gazebo reference="base_laser">
    <!-- <gravity>true</gravity> -->
    <!-- Gazebo has fixed set of Sensors types. Check them out here <> -->
    <sensor name="laser" type="ray">
      <!-- Add in your sensor characteristics -->
      <pose> 0 0 0 0 0 0 </pose>
      <visualise>true</visualise>
      <update_rate>40</update_rate>
      <!-- <always_on>true</always_on> -->
      <ray>
        <scan>
          <horizontal>
            <samples>720</samples>
            <resolution>1</resolution>
            <min_angle>-1.570796</min_angle>
            <max_angle>1.570796</max_angle>
          </horizontal>
        </scan>
        <range>
          <min>0.10</min>
          <max>30.0</max>
          <resolution>0.01</resolution>
        </range>
        <noise>
          <type>gaussian</type>
          <mean>0.0</mean>
          <stddev>0.01</stddev>
        </noise>
      </ray>
      <plugin filename="libgazebo_ros_laser.so" name="gazebo_ros_head_hokuyo_controller">
        <!-- Use topic name as /my_robot/scan -->
        <topicName>/robot_car_rev08/laser_scan</topicName>
        <frameName>laser_frame</frameName>
      </plugin>
    </sensor>
  </gazebo>
  <!--  Gazebo plugin for control here is already added for you -->
  <gazebo>
    <plugin filename="libgazebo_ros_control.so" name="gazebo_ros_control">
      <robotNamespace>/robot_car_rev08</robotNamespace>
      <robotSimType>gazebo_ros_control/DefaultRobotHWSim</robotSimType>
      <legacyModeNS>true</legacyModeNS>
    </plugin>
  </gazebo>
  <!-- Create a joint between your robot and sensor -->
  <joint name="sensor_joint" type="fixed">
    <origin rpy="0 0 0" xyz="0.44 0 0.2032"/>
    <parent link="dummy_link"/>
    <child link="base_laser"/>
  </joint>
  <!--<material name="red">-->
  <!--  <color rgba="0.8 0.0 0.0 1.0"/>-->
  <!--</material>-->
  <!--<material name="blue">-->
  <!-- <color rgba="0.0 0.0 0.8 1.0"/>-->
  <!--</material>-->
  <!--<material name="black">-->
  <!--  <color rgba="0.0 0.0 0.0 1.0"/>-->
  <!--</material>-->
  <!--<material name="dark">-->
  <!--  <color rgba="0.3 0.3 0.3 1.0"/>-->
  <!--</material>-->
  <gazebo reference="chassis">
    <material>Gazebo/Red</material>
  </gazebo>
  <gazebo reference="front_left_steering">
    <material>Gazebo/Blue</material>
  </gazebo>
  <gazebo reference="front_right_steering">
    <material>Gazebo/Blue</material>
  </gazebo>
  <gazebo reference="front_left_wheel">
    <material>Gazebo/FlatBlack</material>
  </gazebo>
  <gazebo reference="front_right_wheel">
    <material>Gazebo/FlatBlack</material>
  </gazebo>
  <gazebo reference="rear_wheel">
    <material>Gazebo/FlatBlack</material>
  </gazebo>
</robot>
